Workbook

Sheet Sheet1
A1: ROW UNSTURCHED DATA DY05-06-DY07-DY01-DY10-DY36-DY19
A5: SAPCODE | B5: PTS CODE | C5: BIN LOCATION/ YARD | D5: QUNT(FOUNDED) | E5: REMARK | F5: JDPV CODE | G5: MATCHED MATERIAL
A6: 2000262034 | B6: 2000262034-16'' | C6: DY07-A-04-0 | D6: 4
A7: 2000303221 | B7: 2000303221-5'' | C7: DY05-D-11-0 | D7: 2
A8: 2001512954 | B8: 2001512954-? | C8: DY06-C-08-0 | D8: 78 | F8: 4571 | G8: MATCHED
A9: 2485739012 | B9: 2485739012-16'' | C9: DY08-B-02-0 | D9: 24
A10: 2485739012 | B10: QWDL92K1-8'' | C10: DY019-E-07-0 | D10: 55
A11: 8247619053 | B11: 8247619053-11'' | C11: DY36-A-09-0 | D11: 2
B12: LMNO45D2-12'' | C12: DY19-D-03-0 | D12: 11
A13: 4182765093 | B13: 4182765093-7'' | C13: DY01-B-06-0 | D13: 25
A14: 4182765093 | B14: RTYU12K9-4'' | C14: DY07-C-10-0 | D14: 5
A15: 8625930174 | B15: GHJK77L2-10'' | C15: DY05-A-01-0 | D15: 59
A16: 4809273516 | B16: POIU78H2-5'' | C16: DY06-D-12-0 | D16: 55 | G16: MATCHED
B17: XXXXXXXX-8'' | C17: DY08-E-05-0 | D17: 2
A18: 2841736905 | B18: 2841736905-10'' | C18: DY019-B-11-0 | D18: 2
A19: 2841736905 | B19: ZXCV11M7-5'' | C19: DY36-C-04-0 | D19: 52
A20: 8652147039 | B20: 8652147039-12'' | C20: DY19-A-08-0 | D20: 18
A21: 8652147039 | B21: XXXXXXXX-6'' | C21: DY01-D-02-0 | D21: 28
A22: 4826037195 | B22: 4826037195-15'' | C22: DY07-E-06-0 | D22: 1
A23: 4825037195 | B23: MNBV66F1-13'' | C23: DY05-B-09-0 | D23: 7
A24: 2847509132 | B24: XXXXXXX-3'' | C24: DY06-A-03-0 | D24: 2
B25: WSXC44K7-7'' | C25: DY08-D-07-0 | D25: 1
A26: 4179602853 | B26: QAZX99L8-2'' | C26: DY019-C-10-0 | D26: 91
A27: 8457425093 | B27: RFVT87M3-9'' | C27: DY36-B-01-0 | D27: 711
A28: 4809273516 | B28: 4809273516-14'' | C28: DY19-E-12-0 | D28: 8
B29: YHNU34D8-3'' | C29: DY01-C-05-0 | D29: 5
A30: 2845097316 | B30: 2845097316-10'' | C30: DY07-D-08-0 | D30: 198
B31: IKOL45P9-5'' | C31: DY05-E-02-0 | D31: 1
A32: 8620457139 | B32: 8620457139-13'' | C32: DY06-B-11-0 | D32: 618
B33: ZMNB98F4-2'' | C33: DY08-A-06-0 | D33: 5
A34: 4827169053 | B34: 4827169053-12'' | C34: DY019-D-04-0 | D34: 1
B35: ASZX64L9-7'' | C35: DY36-E-07-0 | D35: 89
A36: 2483610975 | B36: 2483610975-5'' | C36: DY19-C-09-0 | D36: 4 | G36: MATCHED
B37: TYUI88P2-6'' | C37: DY01-A-03-0 | D37: 56
A38: 8631742095 | B38: 8631742095-11'' | C38: DY07-B-12-0 | D38: 2
A39: 8631742595 | B39: XXXXXXXX-10'' | C39: DY05-C-06-0 | D39: 59

Sheet Sheet2
A1: LC1 NOT FOUND MATERIAL DY05-06-DY07-DY01-DY10-DY36-DY19
A5: JDPV CODE | B5: SAPCODE | C5: PTS CODE | D5: BIN LOCATION | E5: QUNT(NEED) | F5: REMARK | G5: SUPERVISOUR | H5: FOUNDED | I5: TRACK SAP | J5: TRACK PTS | K5: MATCHED MATERIAL
A6: 4827 | B6: 2000262034 | C6: 2000262034-12'' | D6: DY07-A-04-0 | E6: 5.8 | H6: 4 | I6: =IF(ISNA(VLOOKUP(B2,Sheet1!A:D,1,FALSE)),"",B2) | J6: =IF(ISNA(VLOOKUP(C2,Sheet1!B:D,1,FALSE)),"",C2)
A7: 19365 | B7: 2000303221 | C7: QWDL92K1-6'' | D7: DY05-D-11-0 | E7: 19.84 | F7: HYDRA REQURIED DY07-E02-0 | G7: AMAR | H7: 18 | I7: N/A | J7: N/A
A8: 8472 | B8: 2001512954 | C8: 2001512954-7'' | D8: DY06-C-08-0 | E8: 25 | G8: KALPESH | H8: 4 | I8: N/A | J8: N/A
A9: 50291 | B9: 2485739012 | C9: LMNO45D2-9'' | D9: DY08-B-02-0 | E9: 3.2 | G9: RAKESH | H9: 3.2
A10: 2648 | B10: 8247619053 | C10: 8247619053-11'' | D10: DY019-E-07-0 | E10: 26 | G10: AMAR | H10: 0
A11: 91837 | B11: 4182765093 | C11: RTYU12K9-4'' | D11: DY36-A-09-0 | E11: 25 | G11: AMAR | H11: 4
A12: 7405 | B12: 8625930174 | C12: 8625930174-13'' | D12: DY19-D-03-0 | E12: 48 | G12: RAKESH | H12: 10
A13: 36192 | B13: 4802759136 | C13: ABCL88F6-8'' | D13: DY01-B-06-0 | E13: 67 | G13: AMAR | H13: 80
A14: 2850 | B14: 2841736905 | C14: 2841736905-10'' | D14: DY07-C-10-0 | E14: 9 | G14: KALPESH | H14: 0
A15: 67341 | B15: 8652147039 | C15: GHJK77L2-10'' | D15: DY05-A-01-0 | E15: 5 | G15: KANTI | H15: 98
A16: 9042 | B16: 4826037195 | C16: 4826037195-15'' | D16: DY06-D-12-0 | E16: 9 | G16: AMAR | H16: 14
A17: 12857 | B17: 2847509132 | C17: TYUI33P8-3'' | D17: DY08-E-05-0 | E17: 27 | G17: RAKESH | H17: 5
A18: 7603 | B18: 8617425093 | C18: 8617425093-11'' | D18: DY019-B-11-0 | E18: 49 | G18: KALPESH | H18: 5
A19: 45928 | B19: 4809273516 | C19: POIU78H2-5'' | D19: DY36-C-04-0 | E19: 55 | G19: AMAR | H19: 55 | I19: 4809273516 | J19: POIU78H2-5''
A20: 3176 | B20: 2845097316 | C20: 2845097316-10'' | D20: DY19-A-08-0 | E20: 25 | G20: KALPESH | H20: 40
A21: 84520 | B21: 8620457139 | C21: BNML22K4-6'' | D21: DY01-D-02-0 | E21: 225 | G21: KALPESH | H21: 4
A22: 6924 | B22: 4827169053 | C22: 4827169053-12'' | D22: DY07-E-06-0 | E22: 250 | G22: KANTI | H22: 5
A23: 15083 | B23: 8243509716 | C23: ZXCV11M7-4'' | D23: DY05-B-09-0 | E23: 25 | G23: AMAR | H23: 0
A24: 7381 | B24: 2846197350 | C24: 2846197350-9'' | D24: DY06-A-03-0 | E24: 54 | G24: AMAR | H24: 45
A25: 96425 | B25: 4189052736 | C25: LKJH55D9-7'' | D25: DY08-D-07-0 | E25: 51 | G25: RAKESH | H25: 16 | I25: 4189052736 | J25: LKJH55D9-7''
A26: 2819 | B26: 8631742095 | C26: 8631742095-11'' | D26: DY019-C-10-0 | E26: 21 | G26: RAKESH | H26: 70
A27: 50734 | B27: 2496810357 | C27: MNBV66F1-13'' | D27: DY36-B-01-0 | E27: 15 | G27: AMAR | H27: 4
A28: 4582 | B28: 8239507164 | C28: 8239507164-8'' | D28: DY19-E-12-0 | E28: 36 | G28: KALPESH | H28: 42
A29: 19370 | B29: 4179602853 | C29: QAZX99L8-2'' | D29: DY01-C-05-0 | E29: 22 | G29: KANTI | H29: 10
A30: 6752 | B30: 2489073516 | C30: 2489073516-3'' | D30: DY07-D-08-0 | E30: 55 | G30: AMAR | H30: 85
A31: 82049 | B31: 4821903765 | C31: RFVT87M3-9'' | D31: DY05-E-02-0 | E31: 35 | G31: KANTI | H31: 0
A32: 4518 | B32: 8241905376 | C32: 8241905376-6'' | D32: DY06-B-11-0 | E32: 54 | G32: KANTI | H32: 4
A33: 27963 | B33: 4193057862 | C33: TGBY65L2-12'' | D33: DY08-A-06-0 | E33: 85 | G33: KALPESH | H33: 40
A34: 9341 | B34: 2483610975 | C34: 2483610975-5'' | D34: DY019-D-04-0 | E34: 40 | G34: RAKESH | H34: 4 | I34: 2483610975 | J34: 2483610975-5''
A35: 60825 | B35: 8237164095 | C35: UJMI76K1-6'' | D35: DY36-E-07-0 | E35: 45 | G35: KANTI | H35: 20
A36: 7124 | B36: 4172936508 | C36: 4172936508-8'' | D36: DY19-C-09-0 | E36: 15 | G36: KALPESH | H36: 9
A37: 35698 | B37: 2495731068 | C37: OPLK21D7-11'' | D37: DY01-A-03-0 | E37: 18 | G37: RAKESH | H37: 84
A38: 4890 | B38: 4827169054 | C38: ASZX64L9-8'' | D38: DY07-B-12-0 | E38: 4 | G38: KALPESH | H38: 0
A39: 92157 | B39: 8243509717 | C39: TYUI88P2-6'' | D39: DY05-C-06-0 | E39: 8 | G39: RAKESH | H39: 80
E79: 594
E80: 594
E81: 594
E82: 594
...

Sheet Sheet3
A1: Final_Analysis
A5: SAP_Code | B5: Bin_Location | C5: Expected_Qty | D5: Found_Qty | E5: Missing_Qty | F5: Status | G5: Location_Status | H5: Issue_Type | I5: Yard
A6: 2000262034 | B6: DY07-A-04-0 | C6: =IFERROR(VLOOKUP(A6,Sheet2!B:E,4,FALSE),0) -> 5.8 | D6: =IFERROR(VLOOKUP(A6,Sheet1!A:D,4,FALSE),0) -> 4 | E6: =C6 - D6 -> 1.8 | F6: =IF(D6=C6,"Matched", IF(D6=0,"Missing", IF(D6>C6,"Extra","Short"))) -> Short | G6: =IFERROR(IF(B6=VLOOKUP(A6,Sheet1!A:C,3,FALSE),"Correct Location","Misplaced"),"Not Found Data") -> Correct Location | H6: =IF(F6="Missing","System Issue", IF(F6="Extra","Excess Inventory", IF(G6="Misplaced","Location Error","OK"))) -> OK | I6: =LEFT(B6,4) -> DY07
A7: 2000303221 | B7: DY05-D-11-0 | C7: =IFERROR(VLOOKUP(A7,Sheet2!B:E,4,FALSE),0) -> 19.84 | D7: =IFERROR(VLOOKUP(A7,Sheet1!A:D,4,FALSE),0) -> 2 | E7: =C7 - D7 -> 17.84 | F7: =IF(D7=C7,"Matched", IF(D7=0,"Missing", IF(D7>C7,"Extra","Short"))) -> Short | G7: =IFERROR(IF(B7=VLOOKUP(A7,Sheet1!A:C,3,FALSE),"Correct Location","Misplaced"),"Not Found Data") -> Correct Location | H7: =IF(F7="Missing","System Issue", IF(F7="Extra","Excess Inventory", IF(G7="Misplaced","Location Error","OK"))) -> OK | I7: =LEFT(B7,4) -> DY05
A8: 2001512954 | B8: DY06-C-08-0 | C8: =IFERROR(VLOOKUP(A8,Sheet2!B:E,4,FALSE),0) -> 25 | D8: =IFERROR(VLOOKUP(A8,Sheet1!A:D,4,FALSE),0) -> 78 | E8: =C8 - D8 -> -53 | F8: =IF(D8=C8,"Matched", IF(D8=0,"Missing", IF(D8>C8,"Extra","Short"))) -> Extra | G8: =IFERROR(IF(B8=VLOOKUP(A8,Sheet1!A:C,3,FALSE),"Correct Location","Misplaced"),"Not Found Data") -> Correct Location | H8: =IF(F8="Missing","System Issue", IF(F8="Extra","Excess Inventory", IF(G8="Misplaced","Location Error","OK"))) -> Excess Inventory | I8: =LEFT(B8,4) -> DY06
A9: 2485739012 | B9: DY08-B-02-0 | C9: =IFERROR(VLOOKUP(A9,Sheet2!B:E,4,FALSE),0) -> 3.2 | D9: =IFERROR(VLOOKUP(A9,Sheet1!A:D,4,FALSE),0) -> 24 | E9: =C9 - D9 -> -20.8 | F9: =IF(D9=C9,"Matched", IF(D9=0,"Missing", IF(D9>C9,"Extra","Short"))) -> Extra | G9: =IFERROR(IF(B9=VLOOKUP(A9,Sheet1!A:C,3,FALSE),"Correct Location","Misplaced"),"Not Found Data") -> Correct Location | H9: =IF(F9="Missing","System Issue", IF(F9="Extra","Excess Inventory", IF(G9="Misplaced","Location Error","OK"))) -> Excess Inventory | I9: =LEFT(B9,4) -> DY08
A10: 8247619053 | B10: DY019-E-07-0 | C10: =IFERROR(VLOOKUP(A10,Sheet2!B:E,4,FALSE),0) -> 26 | D10: =IFERROR(VLOOKUP(A10,Sheet1!A:D,4,FALSE),0) -> 2 | E10: =C10 - D10 -> 24 | F10: =IF(D10=C10,"Matched", IF(D10=0,"Missing", IF(D10>C10,"Extra","Short"))) -> Short | G10: =IFERROR(IF(B10=VLOOKUP(A10,Sheet1!A:C,3,FALSE),"Correct Location","Misplaced"),"Not Found Data") -> Misplaced | H10: =IF(F10="Missing","System Issue", IF(F10="Extra","Excess Inventory", IF(G10="Misplaced","Location Error","OK"))) -> Location Error | I10: =LEFT(B10,4) -> DY01
A11: 4182765093 | B11: DY36-A-09-0 | C11: =IFERROR(VLOOKUP(A11,Sheet2!B:E,4,FALSE),0) -> 25 | D11: =IFERROR(VLOOKUP(A11,Sheet1!A:D,4,FALSE),0) -> 25 | E11: =C11 - D11 -> 0 | F11: =IF(D11=C11,"Matched", IF(D11=0,"Missing", IF(D11>C11,"Extra","Short"))) -> Matched | G11: =IFERROR(IF(B11=VLOOKUP(A11,Sheet1!A:C,3,FALSE),"Correct Location","Misplaced"),"Not Found Data") -> Misplaced | H11: =IF(F11="Missing","System Issue", IF(F11="Extra","Excess Inventory", IF(G11="Misplaced","Location Error","OK"))) -> Location Error | I11: =LEFT(B11,4) -> DY36
A12: 8625930174 | B12: DY19-D-03-0 | C12: =IFERROR(VLOOKUP(A12,Sheet2!B:E,4,FALSE),0) -> 48 | D12: =IFERROR(VLOOKUP(A12,Sheet1!A:D,4,FALSE),0) -> 59 | E12: =C12 - D12 -> -11 | F12: =IF(D12=C12,"Matched", IF(D12=0,"Missing", IF(D12>C12,"Extra","Short"))) -> Extra | G12: =IFERROR(IF(B12=VLOOKUP(A12,Sheet1!A:C,3,FALSE),"Correct Location","Misplaced"),"Not Found Data") -> Misplaced | H12: =IF(F12="Missing","System Issue", IF(F12="Extra","Excess Inventory", IF(G12="Misplaced","Location Error","OK"))) -> Excess Inventory | I12: =LEFT(B12,4) -> DY19
A13: 4802759136 | B13: DY01-B-06-0 | C13: =IFERROR(VLOOKUP(A13,Sheet2!B:E,4,FALSE),0) -> 67 | D13: =IFERROR(VLOOKUP(A13,Sheet1!A:D,4,FALSE),0) -> 0 | E13: =C13 - D13 -> 67 | F13: =IF(D13=C13,"Matched", IF(D13=0,"Missing", IF(D13>C13,"Extra","Short"))) -> Missing | G13: =IFERROR(IF(B13=VLOOKUP(A13,Sheet1!A:C,3,FALSE),"Correct Location","Misplaced"),"Not Found Data") -> Not Found Data | H13: =IF(F13="Missing","System Issue", IF(F13="Extra","Excess Inventory", IF(G13="Misplaced","Location Error","OK"))) -> System Issue | I13: =LEFT(B13,4) -> DY01
A14: 2841736905 | B14: DY07-C-10-0 | C14: =IFERROR(VLOOKUP(A14,Sheet2!B:E,4,FALSE),0) -> 9 | D14: =IFERROR(VLOOKUP(A14,Sheet1!A:D,4,FALSE),0) -> 2 | E14: =C14 - D14 -> 7 | F14: =IF(D14=C14,"Matched", IF(D14=0,"Missing", IF(D14>C14,"Extra","Short"))) -> Short | G14: =IFERROR(IF(B14=VLOOKUP(A14,Sheet1!A:C,3,FALSE),"Correct Location","Misplaced"),"Not Found Data") -> Misplaced | H14: =IF(F14="Missing","System Issue", IF(F14="Extra","Excess Inventory", IF(G14="Misplaced","Location Error","OK"))) -> Location Error | I14: =LEFT(B14,4) -> DY07
A15: 8652147039 | B15: DY05-A-01-0 | C15: =IFERROR(VLOOKUP(A15,Sheet2!B:E,4,FALSE),0) -> 5 | D15: =IFERROR(VLOOKUP(A15,Sheet1!A:D,4,FALSE),0) -> 18 | E15: =C15 - D15 -> -13 | F15: =IF(D15=C15,"Matched", IF(D15=0,"Missing", IF(D15>C15,"Extra","Short"))) -> Extra | G15: =IFERROR(IF(B15=VLOOKUP(A15,Sheet1!A:C,3,FALSE),"Correct Location","Misplaced"),"Not Found Data") -> Misplaced | H15: =IF(F15="Missing","System Issue", IF(F15="Extra","Excess Inventory", IF(G15="Misplaced","Location Error","OK"))) -> Excess Inventory | I15: =LEFT(B15,4) -> DY05
A16: 4826037195 | B16: DY06-D-12-0 | C16: =IFERROR(VLOOKUP(A16,Sheet2!B:E,4,FALSE),0) -> 9 | D16: =IFERROR(VLOOKUP(A16,Sheet1!A:D,4,FALSE),0) -> 1 | E16: =C16 - D16 -> 8 | F16: =IF(D16=C16,"Matched", IF(D16=0,"Missing", IF(D16>C16,"Extra","Short"))) -> Short | G16: =IFERROR(IF(B16=VLOOKUP(A16,Sheet1!A:C,3,FALSE),"Correct Location","Misplaced"),"Not Found Data") -> Misplaced | H16: =IF(F16="Missing","System Issue", IF(F16="Extra","Excess Inventory", IF(G16="Misplaced","Location Error","OK"))) -> Location Error | I16: =LEFT(B16,4) -> DY06
A17: 2847509132 | B17: DY08-E-05-0 | C17: =IFERROR(VLOOKUP(A17,Sheet2!B:E,4,FALSE),0) -> 27 | D17: =IFERROR(VLOOKUP(A17,Sheet1!A:D,4,FALSE),0) -> 2 | E17: =C17 - D17 -> 25 | F17: =IF(D17=C17,"Matched", IF(D17=0,"Missing", IF(D17>C17,"Extra","Short"))) -> Short | G17: =IFERROR(IF(B17=VLOOKUP(A17,Sheet1!A:C,3,FALSE),"Correct Location","Misplaced"),"Not Found Data") -> Misplaced | H17: =IF(F17="Missing","System Issue", IF(F17="Extra","Excess Inventory", IF(G17="Misplaced","Location Error","OK"))) -> Location Error | I17: =LEFT(B17,4) -> DY08
... A39: 8243509717 | B39: DY05-C-06-0 | C39: =IFERROR(VLOOKUP(A39,Sheet2!B:E,4,FALSE),0) -> 8 | D39: =IFERROR(VLOOKUP(A39,Sheet1!A:D,4,FALSE),0) -> 0 | E39: =C39 - D39 -> 8 | F39: =IF(D39=C39,"Matched", IF(D39=0,"Missing", IF(D39>C39,"Extra","Short"))) -> Missing | G39: =IFERROR(IF(B39=VLOOKUP(A39,Sheet1!A:C,3,FALSE),"Correct Location","Misplaced"),"Not Found Data") -> Not Found Data | H39: =IF(F39="Missing","System Issue", IF(F39="Extra","Excess Inventory", IF(G39="Misplaced","Location Error","OK"))) -> System Issue | I39: =LEFT(B39,4) -> DY05
A43: SUMMURY
A44: Total Missing | B44: =COUNTIF(F6:F100,"Missing") -> 16
A45: Total Extra | B45: =COUNTIF(F6:F100,"Extra") -> 7
A46: Total Short | B46: =COUNTIF(F6:F100,"Short") -> 9
A47: Total Matched | B47: =COUNTIF(F6:F100,"Matched") -> 2
A49: Most Critical Issue | B49: Missing
A50: Total Problem Records | B50: 32
